<?xml version="1.0"?>
<robot name="HextechUAV">
    <link name="HextechWorld">
        <inertial>
            <mass value="0"/>
            <inertia ixx="1.0" ixy="0.0" ixz="0.0" iyy="1.0" iyz="0.0" izz="1.0"/>
        </inertial>
    </link>

    <link name="HextechZaxis">
        <inertial>
            <mass value="0.01"/>
            <inertia ixx="1.0" ixy="0.0" ixz="0.0" iyy="1.0" iyz="0.0" izz="1.0"/>
        </inertial>
    </link>

    <joint name="World2Zaxis" type="prismatic">
        <parent link="HextechWorld"/>
        <child link="HextechZaxis"/>
        <axis xyz="0.0 0.0 1.0"/>
        <limit lower="-8.0" upper="8.0" effort="0.0" velocity="100.0"/>
    </joint>

    <link name="HextechXaxis">
        <inertial>
            <mass value="0.01"/>
            <inertia ixx="1.0" ixy="0.0" ixz="0.0" iyy="1.0" iyz="0.0" izz="1.0"/>
        </inertial>
    </link>

    <joint name="Zaxis2Xaxis" type="prismatic">
        <parent link="HextechZaxis"/>
        <child link="HextechXaxis"/>
        <axis xyz="1.0 0.0 0.0"/>
        <limit lower="-18" upper="16" effort="0.0" velocity="100.0"/>
    </joint>

    <link name="UAVbase">
        <inertial>
            <mass value="8.0"/>
            <inertia ixx="0.3" ixy="0.0" ixz="0.0" iyy="0.3" iyz="0.0" izz="0.3"/>
        </inertial>
        <visual>
            <geometry>
                <box size="0.6 0.1 0.1"/>
            </geometry>
            <material name="UAV_blue">
                <color rgba="0.0 0.0 0.8 1.0"/>
            </material>
        </visual>
        <collision>
            <geometry>
                <box size="0.6 0.1 0.1"/>
            </geometry>
        </collision>
    </link>

    <joint name="UAVBase2Zaxis" type="continuous">
        <parent link="HextechXaxis"/>
        <child link="UAVbase"/>
        <axis xyz="0.0 1.0 0.0"/>
    </joint>

    <link name="HextechEngine1">
        <inertial>
            <mass value="1.0"/>
            <inertia ixx="0.1" ixy="0.0" ixz="0.0" iyy="0.1" iyz="0.0" izz="0.1"/>
        </inertial>
        <visual>
            <geometry>
                <cylinder radius="0.1" length="0.3"/>
            </geometry>
            <material name="UAV_red">
                <color rgba="0.8 0.0 0.0 1.0"/>
            </material>
        </visual>
        <collision>
            <geometry>
                <cylinder radius="0.1" length="0.3"/>
            </geometry>
        </collision>
    </link>

    <joint name="base2Engine1" type="fixed">
        <origin xyz="0.3 0.0 0.0" rpy="0.0 0.0 0.0"/>
        <parent link="UAVbase"/>
        <child link="HextechEngine1"/>
    </joint>

    <link name="HextechEngine2">
        <inertial>
            <mass value="1.0"/>
            <inertia ixx="0.1" ixy="0.0" ixz="0.0" iyy="0.1" iyz="0.0" izz="0.1"/>
        </inertial>
        <visual>
            <geometry>
                <cylinder radius="0.1" length="0.3"/>
            </geometry>
            <material name="UAV_red">
                <color rgba="0.8 0.0 0.0 1.0"/>
            </material>
        </visual>
        <collision>
            <geometry>
                <cylinder radius="0.1" length="0.3"/>
            </geometry>
        </collision>
    </link>

    <joint name="base2Engine2" type="fixed">
        <origin xyz="-0.3 0.0 0.0" rpy="0.0 0.0 0.0"/>
        <parent link="UAVbase"/>
        <child link="HextechEngine2"/>
    </joint>

</robot>