<?xml version="1.0"?>
<robot name="catcher">
    <link name="base">
        <inertial>
            <mass value="0.0"/>
            <inertia ixx="0.0" ixy="0.0" ixz="0.0" iyy="0.0" iyz="0.0" izz="0.0"/>
        </inertial>
        <visual>
            <origin xyz="0.0 0.0 0.0" rpy="0.0 0.0 0.0"/>
            <geometry>
                <box size="0.1 0.1 1.0"/>
            </geometry>
            <material name="grey">
                <color rgba="0.5 0.5 0.5 1.0"/>
            </material>
        </visual>
        <collision>
            <origin xyz="0.0 0.0 0.0" rpy="0.0 0.0 0.0"/>
            <geometry>
                <box size="0.1 0.1 1.0"/>
            </geometry>
        </collision>
    </link>

    <link name="x_link">
        <inertial>
            <origin xyz="0.0 0.0 0.0" rpy="0.0 0.0 0.0"/>
            <mass value="1.0"/>
            <inertia ixx="1.0" ixy="0.0" ixz="0.0" iyy="1.0" iyz="0.0" izz="1.0"/>
        </inertial>
        <visual>
            <origin xyz="0.0 0.0 0.0" rpy="0.0 0.0 0.0"/>
            <geometry>
                <box size="1.0 0.1 0.1"/>
            </geometry>
            <material name="grey">
                <color rgba="0.5 0.5 0.5 1.0"/>
            </material>
        </visual>
    </link>

    <joint name="base2x_link" type="prismatic">
        <parent link="base"/>
        <child link="x_link"/>
        <axis xyz="1.0 0.0 0.0"/>
        <origin xyz="0.0 0.0 -0.5" rpy="0.0 0.0 0.0"/>
        <limit lower="-0.5" upper="0.5" limit="20.0"/>
    </joint>

    <link name="y_link">
        <inertial>
            <origin xyz="0.0 0.0 0.0" rpy="0.0 0.0 0.0"/>
            <mass value="1.0"/>
            <inertia ixx="1.0" ixy="0.0" ixz="0.0" iyy="1.0" iyz="0.0" izz="1.0"/>
        </inertial>
        <visual>
            <origin xyz="0.0 0.0 0.0" rpy="0.0 0.0 0.0"/>
            <geometry>
                <box size="0.1 1.0 0.1"/>
            </geometry>
            <material name="grey">
                <color rgba="0.5 0.5 0.5 1.0"/>
            </material>
        </visual>
    </link>

    <joint name="x_link2y_link" type="prismatic">
        <parent link="x_link"/>
        <child link="y_link"/>
        <axis xyz="0.0 1.0 0.0"/>
        <origin xyz="0.5 0.0 0.0" rpy="0.0 0.0 0.0"/>
        <limit lower="-0.5" upper="0.5" limit="20.0"/>
    </joint>

    <link name="z_link">
        <inertial>
            <origin xyz="0.0 0.0 0.0" rpy="0.0 0.0 0.0"/>
            <mass value="1.0"/>
            <inertia ixx="1.0" ixy="0.0" ixz="0.0" iyy="1.0" iyz="0.0" izz="1.0"/>
        </inertial>
        <visual>
            <origin xyz="0.0 0.0 0.0" rpy="0.0 0.0 0.0"/>
            <geometry>
                <box size="0.1 0.1 1.0"/>
            </geometry>
            <material name="grey">
                <color rgba="0.5 0.5 0.5 1.0"/>
            </material>
        </visual>
    </link>

    <joint name="y_link2z_link" type="prismatic">
        <parent link="y_link"/>
        <child link="z_link"/>
        <axis xyz="0.0 0.0 1.0"/>
        <origin xyz="0.0 0.5 0.0" rpy="0.0 0.0 0.0"/>
        <limit lower="-0.5" upper="0.5" limit="20.0"/>
    </joint>

    <link name="holder_top">
        <inertial>
            <origin xyz="0.0 0.0 0.0" rpy="0.0 0.0 0.0"/>
            <mass value="1.0"/>
            <inertia ixx="1.0" ixy="0.0" ixz="0.0" iyy="1.0" iyz="0.0" izz="1.0"/>
        </inertial>
        <visual>
            <origin xyz="0.0 0.0 0.0" rpy="0.0 0.0 0.0"/>
            <geometry>
                <box size="0.1 0.1 0.02"/>
            </geometry>
            <material name="grey">
                <color rgba="0.5 0.5 0.5 1.0"/>
            </material>
        </visual>
    </link>

    <joint name="z_link2holder_top" type="continuous">
        <parent link="z_link"/>
        <child link="holder_top"/>
        <axis xyz="0.0 0.0 1.0"/>
        <origin xyz="0.0 0.0 0.49" rpy="0.0 0.0 0.0"/>
    </joint>

    <link name="holder_left">
        <inertial>
            <origin xyz="0.0 0.0 0.0" rpy="0.0 0.0 0.0"/>
            <mass value="1.0"/>
            <inertia ixx="1.0" ixy="0.0" ixz="0.0" iyy="1.0" iyz="0.0" izz="1.0"/>
        </inertial>
        <visual>
            <origin xyz="0.0 0.0 0.05" rpy="0.0 0.0 0.0"/>
            <geometry>
                <box size="0.1 0.02 0.1"/>
            </geometry>
            <material name="red">
                <color rgba="0.9 0.0 0.0 1.0"/>
            </material>
        </visual>
        <collision>
            <origin xyz="0.0 0.0 0.05" rpy="0.0 0.0 0.0"/>
            <geometry>
                <box size="0.1 0.02 0.1"/>
            </geometry>
        </collision>
        <contact>
            <lateral_friction value="10000.0"/>
            <rolling_friction value="0.0"/>
        </contact>
    </link>

    <link name="holder_right">
        <inertial>
            <origin xyz="0.0 0.0 0.0" rpy="0.0 0.0 0.0"/>
            <mass value="1.0"/>
            <inertia ixx="1.0" ixy="0.0" ixz="0.0" iyy="1.0" iyz="0.0" izz="1.0"/>
        </inertial>
        <visual>
            <origin xyz="0.0 0.0 0.05" rpy="0.0 0.0 0.0"/>
            <geometry>
                <box size="0.1 0.02 0.1"/>
            </geometry>
            <material name="red">
                <color rgba="0.9 0.0 0.0 1.0"/>
            </material>
        </visual>
        <collision>
            <origin xyz="0.0 0.0 0.05" rpy="0.0 0.0 0.0"/>
            <geometry>
                <box size="0.1 0.02 0.1"/>
            </geometry>
        </collision>
        <contact>
            <lateral_friction value="10000.0"/>
            <rolling_friction value="0.0"/>
        </contact>
    </link>

    <joint name="holder_top2holder_left" type="prismatic">
        <origin xyz="0.0 0.05 0.01" rpy="0.0 0.0 0.0"/>
        <parent link="holder_top"/>
        <child link="holder_left"/>
        <axis xyz="0.0 -1.0 0.0"/>
        <limit lower="0.0" upper="0.04"/>
    </joint>

    <joint name="holder_top2holder_right" type="prismatic">
        <origin xyz="0.0 -0.05 0.01" rpy="0.0 0.0 0.0"/>
        <parent link="holder_top"/>
        <child link="holder_right"/>
        <axis xyz="0.0 1.0 0.0"/>
        <limit lower="0.0" upper="0.04"/>
    </joint>

</robot>