<?xml version="1.0"?>
<robot name="car">
    <link name="base_link">
        <visual>
            <geometry>
                <box size="4.0 2.0 1.0"/>
            </geometry>
            <material name="blue">
                <color rgba="0 0 .8 1"/>
            </material>
        </visual>
    </link>

    <link name="wheel_1">
        <visual>
            <geometry>
                <cylinder length="2.0" radius="0.5"/>
            </geometry>
            <material name="green">
                <color rgba="0 0.8 0 1"/>
            </material>
        </visual>
    </link>

    <joint name="base_link_to_wheel_1" type="continuous">
        <parent link="base_link"/>
        <child link="wheel_1"/>
        <axis xyz="0.0 1.0 0.0"/>
    </joint>
</robot>