<?xml version="1.0"?>
<robot name="car">
    <link name="base_link">
        <visual>
            <geometry>
                <box size="4.0 2.0 1.0"/>
            </geometry>
            <material name="blue">
                <color rgba="0 0 .8 1"/>
            </material>
        </visual>
        <inertial>
            <mass value="10.0"/>
            <inertia ixx="10.0" ixy="0.0" ixz="0.0" iyy="10.0" iyz="0.0" izz="10.0"/>
        </inertial>
    </link>

    <link name="wheel_1">
        <visual>
            <geometry>
                <cylinder length="2.0" radius="0.5"/>
            </geometry>
            <material name="green">
                <color rgba="0 .8 0 1"/>
            </material>
            <origin rpy="1.57 0.0 0.0"/>
        </visual>
        <collision>
            <geometry>
                <cylinder radius="0.5" length="2.0"/>
            </geometry>
            <origin rpy="1.57 0.0 0.0"/>
        </collision>
        <inertial>
            <mass value="1.0"/>
            <origin rpy="1.57 0.0 0.0"/>
            <inertia ixx="1.0" ixy="0.0" ixz="0.0" iyy="1.0" iyz="0.0" izz="1.0"/>
        </inertial>
    </link>

    <joint name="base_link_to_wheel_1" type="continuous">
        <parent link="base_link"/>
        <child link="wheel_1"/>
        <axis xyz="0.0 1.0 0.0"/>
        <origin xyz="1.0 0.0 0.5" rpy="0.0 0.0 0.0"/>
    </joint>

    <link name="wheel_2">
        <visual>
            <geometry>
                <cylinder length="2.0" radius="0.5"/>
            </geometry>
            <material name="green">
                <color rgba="0 .8 0 1"/>
            </material>
            <origin rpy="1.57 0.0 0.0"/>
        </visual>
        <collision>
            <geometry>
                <cylinder radius="0.5" length="2.0"/>
            </geometry>
            <origin rpy="1.57 0.0 0.0"/>
        </collision>
        <inertial>
            <mass value="1.0"/>
            <origin rpy="1.57 0.0 0.0"/>
            <inertia ixx="1.0" ixy="0.0" ixz="0.0" iyy="1.0" iyz="0.0" izz="1.0"/>
        </inertial>
    </link>

    <joint name="base_link_to_wheel_2" type="continuous">
        <parent link="base_link"/>
        <child link="wheel_2"/>
        <axis xyz="0.0 1.0 0.0"/>
        <origin xyz="-1.0 0.0 0.5" rpy="0.0 0.0 0.0"/>
    </joint>
</robot>