<?xml version="1.0"?>
<robot name="Mario">
    <link name="World">
        <inertial>
            <origin xyz="0.0 0.0 0.0" rpy="0.0 0.0 0.0"/>
            <mass value="0.0"/>
            <inertia ixx="0.0" ixy="0.0" ixz="0.0" iyy="0.0" iyz="0.0" izz="0.0"/>
        </inertial>
    </link>

    <joint name="World2XAxis" type="prismatic">
        <origin xyz="0.0 0.0 0.0" rpy="0.0 0.0 0.0"/>
        <axis xyz="1.0 0.0 0.0"/>
        <limit lower="-50.0" upper="50.0" effort="0.0"/>
        <parent link="World"/>
        <child link="XAxis"/>
    </joint>

    <link name="XAxis">
        <inertial>
            <origin xyz="0.0 0.0 0.0" rpy="0.0 0.0 0.0"/>
            <mass value="0.01"/>
            <inertia ixx="0.01" ixy="0.0" ixz="0.0" iyy="0.01" iyz="0.0" izz="0.01"/>
        </inertial>
    </link>

    <joint name="XAxis2ZAxis" type="prismatic">
        <origin xyz="0.0 0.0 0.0" rpy="0.0 0.0 0.0"/>
        <parent link="XAxis"/>
        <child link="ZAxis"/>
        <axis xyz="0.0 0.0 -1.0"/>
        <limit lower="-50.0" upper="50.0"/>
    </joint>

    <link name="ZAxis">
        <inertial>
            <origin xyz="0.0 0.0 0.0" rpy="0.0 0.0 0.0"/>
            <mass value="0.01"/>
            <inertia ixx="0.01" ixy="0.0" ixz="0.0" iyy="0.01" iyz="0.0" izz="0.01"/>
        </inertial>
    </link>

    <joint name="ZAxis2body" type="continuous">
        <origin xyz="0.0 0.0 0.0" rpy="0.0 0.0 0.0"/>
        <parent link="ZAxis"/>
        <child link="body"/>
        <axis xyz="0.0 1.0 0.0"/>
    </joint>

    <link name="body">
        <inertial>
            <origin xyz="0.0 0.0 0.0" rpy="0.0 0.0 0.0"/>
            <mass value="5.0"/>
            <inertia ixx="0.5" ixy="0.0" ixz="0.0" iyy="0.5" iyz="0.0" izz="0.5"/>
        </inertial>
        <visual>
            <origin xyz="0.0 0.0 0.0" rpy="0.0 0.0 0.0"/>
            <geometry>
                <box size="0.3 0.2 0.2"/>
            </geometry>
            <material name="red">
                <color rgba="0.8 0.0 0.0 1.0"/>
            </material>
        </visual>
        <collision>
            <origin xyz="0.0 0.0 0.0" rpy="0.0 0.0 0.0"/>
            <geometry>
                <box size="0.3 0.2 0.2"/>
            </geometry>
        </collision>
    </link>

    <joint name="body2thigh" type="fixed">
        <origin xyz="0.0 0.0 0.0" rpy="0.0 0.0 0.0"/>
        <parent link="body"/>
        <child link="thigh"/>
    </joint>

    <link name="thigh">
        <inertial>
            <origin xyz="0.0 0.0 0.25" rpy="0.0 0.0 0.0"/>
            <mass value="0.5"/>
            <inertia ixx="0.05" ixy="0.0" ixz="0.0" iyy="0.05" iyz="0.0" izz="0.05"/>
        </inertial>
        <visual>
            <origin xyz="0.0 0.0 0.25" rpy="0.0 0.0 0.0"/>
            <geometry>
                <cylinder radius="0.05" length="0.5"/>
            </geometry>
            <material name="blue">
                <color rgba="0.0 0.0 1.0 1.0"/>
            </material>
        </visual>
    </link>

    <joint name="engine1" type="continuous">
        <origin xyz="0.0 0.0 0.5" rpy="0.0 0.0 0.0"/>
        <parent link="thigh"/>
        <child link="leg"/>
        <axis xyz="0.0 1.0 0.0"/>
        <limit velocity="30.0"/>
    </joint>

    <link name="leg">
        <inertial>
            <origin xyz="0.0 0.0 0.25" rpy="0.0 0.0 0.0"/>
            <mass value="0.5"/>
            <inertia ixx="0.05" ixy="0.0" ixz="0.0" iyy="0.05" iyz="0.0" izz="0.05"/>
        </inertial>
        <visual>
            <origin xyz="0.0 0.0 0.25" rpy="0.0 0.0 0.0"/>
            <geometry>
                <cylinder radius="0.05" length="0.5"/>
            </geometry>
            <material name="blue">
            </material>
        </visual>
    </link>

    <joint name="engine2" type="continuous">
        <origin xyz="0.0 0.0 0.5" rpy="0.0 0.0 0.0"/>
        <parent link="leg"/>
        <child link="wheel"/>
        <axis xyz="0.0 1.0 0.0"/>
        <limit velocity="30.0"/>
    </joint>

    <link name="wheel">
        <inertial>
            <origin xyz="0.0 0.0 0.0" rpy="0.0 0.0 0.0"/>
            <mass value="1.0"/>
            <inertia ixx="0.5" ixy="0.0" ixz="0.0" iyy="0.5" iyz="0.0" izz="0.5"/>
        </inertial>
        <visual>
            <origin xyz="0.0 0.0 0.0" rpy="1.57 0.0 0.0"/>
            <geometry>
                <cylinder radius="0.2" length="0.1"/>
            </geometry>
            <material name="red">
            </material>
        </visual>
        <collision>
            <origin xyz="0.0 0.0 0.0" rpy="1.57 0.0 0.0"/>
            <geometry>
                <cylinder radius="0.2" length="0.1"/>
            </geometry>
        </collision>
    </link>

</robot>